2025-10-21 13:27:22 - hestia - ERROR - /Volumes/Externo/Ifes/hestia/util/exception_handlers.py:153 - Exceção não tratada: UndefinedError: 'obter_mensagens' is undefined - Path: /cadastro_contratante - IP: 127.0.0.1
Traceback (most recent call last):
  File "/Volumes/Externo/Ifes/hestia/.venv/lib/python3.11/site-packages/starlette/middleware/errors.py", line 164, in __call__
    await self.app(scope, receive, _send)
  File "/Volumes/Externo/Ifes/hestia/.venv/lib/python3.11/site-packages/starlette/middleware/sessions.py", line 85, in __call__
    await self.app(scope, receive, send_wrapper)
  File "/Volumes/Externo/Ifes/hestia/.venv/lib/python3.11/site-packages/starlette/middleware/exceptions.py", line 63, in __call__
    await wrap_app_handling_exceptions(self.app, conn)(scope, receive, send)
  File "/Volumes/Externo/Ifes/hestia/.venv/lib/python3.11/site-packages/starlette/_exception_handler.py", line 53, in wrapped_app
    raise exc
  File "/Volumes/Externo/Ifes/hestia/.venv/lib/python3.11/site-packages/starlette/_exception_handler.py", line 42, in wrapped_app
    await app(scope, receive, sender)
  File "/Volumes/Externo/Ifes/hestia/.venv/lib/python3.11/site-packages/fastapi/middleware/asyncexitstack.py", line 18, in __call__
    await self.app(scope, receive, send)
  File "/Volumes/Externo/Ifes/hestia/.venv/lib/python3.11/site-packages/starlette/routing.py", line 716, in __call__
    await self.middleware_stack(scope, receive, send)
  File "/Volumes/Externo/Ifes/hestia/.venv/lib/python3.11/site-packages/starlette/routing.py", line 736, in app
    await route.handle(scope, receive, send)
  File "/Volumes/Externo/Ifes/hestia/.venv/lib/python3.11/site-packages/starlette/routing.py", line 290, in handle
    await self.app(scope, receive, send)
  File "/Volumes/Externo/Ifes/hestia/.venv/lib/python3.11/site-packages/fastapi/routing.py", line 123, in app
    await wrap_app_handling_exceptions(app, request)(scope, receive, send)
  File "/Volumes/Externo/Ifes/hestia/.venv/lib/python3.11/site-packages/starlette/_exception_handler.py", line 53, in wrapped_app
    raise exc
  File "/Volumes/Externo/Ifes/hestia/.venv/lib/python3.11/site-packages/starlette/_exception_handler.py", line 42, in wrapped_app
    await app(scope, receive, sender)
  File "/Volumes/Externo/Ifes/hestia/.venv/lib/python3.11/site-packages/fastapi/routing.py", line 109, in app
    response = await f(request)
               ^^^^^^^^^^^^^^^^
  File "/Volumes/Externo/Ifes/hestia/.venv/lib/python3.11/site-packages/fastapi/routing.py", line 389, in app
    raw_response = await run_endpoint_function(
                   ^^^^^^^^^^^^^^^^^^^^^^^^^^^^
  File "/Volumes/Externo/Ifes/hestia/.venv/lib/python3.11/site-packages/fastapi/routing.py", line 288, in run_endpoint_function
    return await dependant.call(**values)
           ^^^^^^^^^^^^^^^^^^^^^^^^^^^^^^
  File "/Volumes/Externo/Ifes/hestia/routes/public_routes.py", line 271, in cadastro_contratante_form
    return templates.TemplateResponse("cadastro_contratante.html", {"request": request})
           ^^^^^^^^^^^^^^^^^^^^^^^^^^^^^^^^^^^^^^^^^^^^^^^^^^^^^^^^^^^^^^^^^^^^^^^^^^^^^
  File "/Volumes/Externo/Ifes/hestia/.venv/lib/python3.11/site-packages/starlette/templating.py", line 210, in TemplateResponse
    return _TemplateResponse(
           ^^^^^^^^^^^^^^^^^^
  File "/Volumes/Externo/Ifes/hestia/.venv/lib/python3.11/site-packages/starlette/templating.py", line 41, in __init__
    content = template.render(context)
              ^^^^^^^^^^^^^^^^^^^^^^^^
  File "/Volumes/Externo/Ifes/hestia/.venv/lib/python3.11/site-packages/jinja2/environment.py", line 1295, in render
    self.environment.handle_exception()
  File "/Volumes/Externo/Ifes/hestia/.venv/lib/python3.11/site-packages/jinja2/environment.py", line 942, in handle_exception
    raise rewrite_traceback_stack(source=source)
  File "templates/cadastro_contratante.html", line 4, in top-level template code
    {% set dados = dados if dados is defined else {} %}
    ^^^^^^^^^^^^^^^^^^^^^^^^^
  File "templates/base_simples.html", line 31, in top-level template code
    {{ obter_mensagens(request) | tojson }}
    ^^^^^^^^^^^^^^^^^^^^^^^^^
  File "/Volumes/Externo/Ifes/hestia/.venv/lib/python3.11/site-packages/jinja2/utils.py", line 92, in from_obj
    if hasattr(obj, "jinja_pass_arg"):
       ^^^^^^^^^^^^^^^^^^^^^^^^^^^^^^
jinja2.exceptions.UndefinedError: 'obter_mensagens' is undefined
2025-10-22 00:47:05 - hestia - ERROR - /Volumes/Externo/Ifes/hestia/data/usuario/usuario_repo.py:49 - Erro ao inserir usuário: UNIQUE constraint failed: usuario.cpf
Traceback (most recent call last):
  File "/Volumes/Externo/Ifes/hestia/data/usuario/usuario_repo.py", line 44, in inserir
    cursor.execute(INSERIR_USUARIO, parametros)
sqlite3.IntegrityError: UNIQUE constraint failed: usuario.cpf
2025-10-22 00:47:36 - hestia - ERROR - /Volumes/Externo/Ifes/hestia/data/usuario/usuario_repo.py:49 - Erro ao inserir usuário: UNIQUE constraint failed: usuario.cpf
Traceback (most recent call last):
  File "/Volumes/Externo/Ifes/hestia/data/usuario/usuario_repo.py", line 44, in inserir
    cursor.execute(INSERIR_USUARIO, parametros)
sqlite3.IntegrityError: UNIQUE constraint failed: usuario.cpf
2025-10-22 00:48:19 - hestia - ERROR - /Volumes/Externo/Ifes/hestia/data/usuario/usuario_repo.py:50 - Erro ao inserir usuário: UNIQUE constraint failed: usuario.cpf
Traceback (most recent call last):
  File "/Volumes/Externo/Ifes/hestia/data/usuario/usuario_repo.py", line 45, in inserir
    cursor.execute(INSERIR_USUARIO, parametros)
sqlite3.IntegrityError: UNIQUE constraint failed: usuario.cpf
2025-10-22 07:49:31 - hestia - ERROR - /Volumes/Externo/Ifes/hestia/data/usuario/usuario_repo.py:50 - Erro ao inserir usuário: UNIQUE constraint failed: usuario.cpf
Traceback (most recent call last):
  File "/Volumes/Externo/Ifes/hestia/data/usuario/usuario_repo.py", line 45, in inserir
    cursor.execute(INSERIR_USUARIO, parametros)
sqlite3.IntegrityError: UNIQUE constraint failed: usuario.cpf
2025-10-22 12:58:52 - hestia - ERROR - /Volumes/Externo/Ifes/hestia/data/usuario/usuario_repo.py:50 - Erro ao inserir usuário: UNIQUE constraint failed: usuario.cpf
Traceback (most recent call last):
  File "/Volumes/Externo/Ifes/hestia/data/usuario/usuario_repo.py", line 45, in inserir
    cursor.execute(INSERIR_USUARIO, parametros)
sqlite3.IntegrityError: UNIQUE constraint failed: usuario.cpf
